Workbook

Sheet IPM Regions to LDAs and Zones
A1: IPM Regions | B1: Locational Deliverability Areas or LDAs (27 unique boldfaces) | C1: Transmission/Load Zones (21 unique black boldfaces) | D1: Parent 2 | E1: Parent 1 | F1: Parent 0 | G1: level | I1: IPM Regions | J1: Transmission Zones | K1: fraction
A2: PJM_COMD | B2: ComEd | C2: ComEd | D2: Western PJM [WEST] | E2: RTO | F2: RTO | G2: 2 | I2: PJM_EMAC | J2: AE [AECO] | K2: 0.085790538 | L2: =_xlfn.XLOOKUP(J2,'Load Zones to States'!I:I,'Load Zones to States'!J:J,,0,1) -> AE
A3: PJM_West | B3: AEP | C3: AEP | D3: Western PJM [WEST] | E3: RTO | F3: RTO | G3: 2 | J3: PSEG [PS] | K3: 0.31876588 | L3: =_xlfn.XLOOKUP(J3,'Load Zones to States'!I:I,'Load Zones to States'!J:J,,0,1) -> PS
A4: PJM_West | B4: Dayton [DAY] | C4: Dayton [DAY] | D4: Western PJM [WEST] | E4: RTO | F4: RTO | G4: 2 | J4: PECO | K4: 0.2630234 | L4: =_xlfn.XLOOKUP(J4,'Load Zones to States'!I:I,'Load Zones to States'!J:J,,0,1) -> PECO
A5: PJM_West | B5: Duquesne [DLCO or DUQ] | C5: Duquesne [DLCO or DUQ] | D5: Western PJM [WEST] | E5: RTO | F5: RTO | G5: 2 | J5: JCPL | K5: 0.19285811 | L5: =_xlfn.XLOOKUP(J5,'Load Zones to States'!I:I,'Load Zones to States'!J:J,,0,1) -> JCPL
A6: PJM_AP | B6: APS [AP] | C6: APS [AP] | D6: Western PJM [WEST] | E6: RTO | F6: RTO | G6: 2 | J6: DPL | K6: 0.1270288 | L6: =_xlfn.XLOOKUP(J6,'Load Zones to States'!I:I,'Load Zones to States'!J:J,,0,1) -> DPL
A7: PJM_ATSI | B7: ATSI | C7: ATSI | D7: Western PJM [WEST] | E7: RTO | F7: RTO | G7: 2 | J7: RECO | K7: 0.012533284 | L7: =_xlfn.XLOOKUP(J7,'Load Zones to States'!I:I,'Load Zones to States'!J:J,,0,1) -> RECO
A8: PJM_West | B8: DEOK | C8: DEOK | D8: Western PJM [WEST] | E8: RTO | F8: RTO | G8: 2
A9: PJM_West | B9: EKPC | C9: EKPC | D9: Western PJM [WEST] | E9: RTO | F9: RTO | G9: 2 | I9: PJM_SMAC | J9: BGE | K9: 0.5232167 | L9: =_xlfn.XLOOKUP(J9,'Load Zones to States'!I:I,'Load Zones to States'!J:J,,0,1) -> BGE
A10: PJM_West | C10: OVEC | D10: Western PJM [WEST] | E10: RTO | F10: RTO | G10: 2 | J10: PEPCO | K10: 0.4767833 | L10: =_xlfn.XLOOKUP(J10,'Load Zones to States'!I:I,'Load Zones to States'!J:J,,0,1) -> PEPCO
A11: PJM_Dom | B11: Dominion [DOM] | C11: Dominion [DOM] | D11: RTO | E11: RTO | F11: RTO | G11: 1
A12: PJM_WMAC | B12: MetEd | C12: MetEd | D12: WMAAC | E12: MAAC | F12: RTO | G12: 3 | I12: PJM_WMAC | J12: MetEd | K12: 0.29032707 | L12: =_xlfn.XLOOKUP(J12,'Load Zones to States'!I:I,'Load Zones to States'!J:J,,0,1) -> METED
A13: PJM_WMAC | B13: PPL [PL]+UGI | C13: PPL [PL]+UGI | D13: WMAAC | E13: MAAC | F13: RTO | G13: 3 | J13: PPL [PL]+UGI | K13: 0.70967293 | L13: =_xlfn.XLOOKUP(J13,'Load Zones to States'!I:I,'Load Zones to States'!J:J,,0,1) -> PL
A14: PJM_PENE | B14: Penelec [PENLC] | C14: Penelec [PENLC] | D14: WMAAC | E14: MAAC | F14: RTO | G14: 3
A15: PJM_EMAC | B15: AE [AECO] | C15: AE [AECO] | D15: EMAAC | E15: MAAC | F15: RTO | G15: 3 | I15: PJM_West | J15: AEP | K15: 0.62097633 | L15: =_xlfn.XLOOKUP(J15,'Load Zones to States'!I:I,'Load Zones to States'!J:J,,0,1) -> AEP
A16: PJM_EMAC | B16: PSEG [PS] | C16: PSEG [PS] | D16: EMAAC | E16: MAAC | F16: RTO | G16: 3 | J16: Dayton [DAY] | K16: 0.09103539 | L16: =_xlfn.XLOOKUP(J16,'Load Zones to States'!I:I,'Load Zones to States'!J:J,,0,1) -> DAY
A17: PJM_EMAC | B17: PECO | C17: PECO | D17: EMAAC | E17: MAAC | F17: RTO | G17: 3 | J17: Duquesne [DLCO or DUQ] | K17: 0.077469871 | L17: =_xlfn.XLOOKUP(J17,'Load Zones to States'!I:I,'Load Zones to States'!J:J,,0,1) -> DLCO
A18: PJM_EMAC | B18: JCPL | C18: JCPL | D18: EMAAC | E18: MAAC | F18: RTO | G18: 3 | J18: DEOK | K18: 0.1479864 | L18: =_xlfn.XLOOKUP(J18,'Load Zones to States'!I:I,'Load Zones to States'!J:J,,0,1) -> DEOK
A19: PJM_EMAC | B19: DPL | C19: DPL | D19: EMAAC | E19: MAAC | F19: RTO | G19: 3 | J19: EKPC | K19: 0.060062068 | L19: =_xlfn.XLOOKUP(J19,'Load Zones to States'!I:I,'Load Zones to States'!J:J,,0,1) -> EKPC
A20: PJM_EMAC | C20: RECO | D20: EMAAC | E20: MAAC | F20: RTO | G20: 3 | J20: OVEC | K20: 0.0024699409 | L20: =_xlfn.XLOOKUP(J20,'Load Zones to States'!I:I,'Load Zones to States'!J:J,,0,1) -> OVEC
A21: PJM_SMAC | B21: BGE | C21: BGE | D21: SWMAAC | E21: MAAC | F21: RTO | G21: 3 | I21: Notes: Average of fraction of Net Peak Load (MW) 2022-2031, see inputs/CAPSTF - Model Inputs 28 03 2023.xlsx, download from: https://www.pjm.com/-/media/DotCom/committees-groups/task-forces/capstf/postings/analysis-1-inputs-annual-outputs-final.zip; See IPM Regions fractions sheet for detailed calculation.
A22: PJM_SMAC | B22: PEPCO | C22: PEPCO | D22: SWMAAC | E22: MAAC | F22: RTO | G22: 3
B23: Western PJM [WEST] | C23: Western PJM [WEST] | D23: RTO | E23: RTO | F23: RTO | G23: 1
A24: PJM_ATSI | B24: Cleveland [ATSI-Cleveland] | C24: ATSI | D24: Western PJM [WEST] | E24: RTO | F24: RTO | G24: 2
B25: MAAC | C25: MAAC | D25: RTO | E25: RTO | F25: RTO | G25: 1
B26: WMAAC | C26: WMAAC | D26: MAAC | E26: RTO | F26: RTO | G26: 2
B27: EMAAC | C27: EMAAC | D27: EMAAC | E27: MAAC | F27: RTO | G27: 3
A28: PJM_EMAC | B28: PSEG northern region [PSEG N or PSNORTH] | C28: PSEG [PS] | D28: EMAAC | E28: MAAC | F28: RTO | G28: 3
A29: PJM_EMAC | B29: DPL southern region | C29: DPL | D29: EMAAC | E29: MAAC | F29: RTO | G29: 3
B30: SWMAAC | C30: SWMAAC | D30: SWMAAC | E30: MAAC | F30: RTO | G30: 3
A31: Notes: At high level, RTO := 1) Western PJM, 2) MAAC (EMAAC, WMAAC, SWMAAC), and 3) Dominion
R32: Notes: See https://www.pjm.com/library/-/media/B7455E69D97B45FFB390EEFAD84AD50D.ashx
R33: PJM Zone | S33: ZONE
R34: APS | S34: Allegheny Power Systems (AP)
R35: AEP | S35: American Electric Power (AEP)
R36: ATSI | S36: American Transmission Systems, Inc. (ATSI)
R37: AE | S37: Atlantic City Electric Co. (AE)
R38: BGE | S38: Baltimore Gas and Electric Co. (BGE)
R39: ComEd | S39: Commonwealth Edison Company (ComEd)
R40: DAY | S40: Dayton Power & Light Co. (DAY)
...

Sheet IPM Regions fractions
B1: Net Peak Load (MW)
A2: IPM Regions | B2: zone | C2: 2022 | D2: 2023 | E2: 2024 | F2: 2025 | G2: 2026 | H2: 2027 | I2: 2028 | J2: 2029 | K2: 2030 | L2: 2031
A3: PJM_AP | B3: APS | C3: 8768 | D3: 8831 | E3: 8890 | F3: 8935 | G3: 8951 | H3: 8979 | I3: 9005 | J3: 9039 | K3: 9081 | L3: 9120
A4: PJM_ATSI | B4: ATSI | C4: 12341 | D4: 12438 | E4: 12545 | F4: 12575 | G4: 12630 | H4: 12621 | I4: 12644 | J4: 12671 | K4: 12728 | L4: 12731
A5: PJM_COMD | B5: COMED | C5: 21149 | D5: 21090 | E5: 21073 | F5: 21016 | G5: 21008 | H5: 21020 | I5: 21016 | J5: 21085 | K5: 21121 | L5: 21146
A6: PJM_Dom | B6: DOM | C6: 20965 | D6: 21617 | E6: 22376 | F6: 23230 | G6: 24056 | H6: 24410 | I6: 24809 | J6: 25217 | K6: 25598 | L6: 26001 | Z6: AVG
A7: PJM_EMAC | B7: AE | C7: 2720 | D7: 2729 | E7: 2738 | F7: 2754 | G7: 2764 | H7: 2774 | I7: 2786 | J7: 2804 | K7: 2822 | L7: 2841 | N7: PJM_EMAC | O7: AE | P7: =C7/SUM(C$7:C$12) -> 0.085483516 | Q7: =D7/SUM(D$7:D$12) -> 0.085529821 | R7: =E7/SUM(E$7:E$12) -> 0.085429017 | S7: =F7/SUM(F$7:F$12) -> 0.085730295 | T7: =G7/SUM(G$7:G$12) -> 0.085827847 | U7: =H7/SUM(H$7:H$12) -> 0.085935564 | V7: =I7/SUM(I$7:I$12) -> 0.085947864 | W7: =J7/SUM(J$7:J$12) -> 0.08594636 | ... Y7: =L7/SUM(L$7:L$12) -> 0.086083083 | Z7: =AVERAGE(P7:Y7) -> 0.085790538
B8: DPL | C8: 4024 | D8: 4045 | E8: 4064 | F8: 4082 | G8: 4092 | H8: 4108 | I8: 4126 | J8: 4148 | K8: 4174 | L8: 4199 | O8: DPL | P8: =C8/SUM(C$7:C$12) -> 0.12646532 | Q8: =D8/SUM(D$7:D$12) -> 0.12677469 | R8: =E8/SUM(E$7:E$12) -> 0.12680187 | S8: =F8/SUM(F$7:F$12) -> 0.1270701 | T8: =G8/SUM(G$7:G$12) -> 0.12706496 | U8: =H8/SUM(H$7:H$12) -> 0.12726146 | V8: =I8/SUM(I$7:I$12) -> 0.12728675 | W8: =J8/SUM(J$7:J$12) -> 0.12714176 | ... Y8: =L8/SUM(L$7:L$12) -> 0.12723086 | Z8: =AVERAGE(P8:Y8) -> 0.1270288
B9: JCPL | C9: 6177 | D9: 6176 | E9: 6180 | F9: 6183 | G9: 6197 | H9: 6218 | I9: 6250 | J9: 6284 | K9: 6320 | L9: 6354 | O9: JCPL | P9: =C9/SUM(C$7:C$12) -> 0.19412929 | Q9: =D9/SUM(D$7:D$12) -> 0.19356254 | R9: =E9/SUM(E$7:E$12) -> 0.19282371 | S9: =F9/SUM(F$7:F$12) -> 0.19247292 | T9: =G9/SUM(G$7:G$12) -> 0.19242951 | U9: =H9/SUM(H$7:H$12) -> 0.19262701 | V9: =I9/SUM(I$7:I$12) -> 0.19281197 | W9: =J9/SUM(J$7:J$12) -> 0.19261303 | ... Y9: =L9/SUM(L$7:L$12) -> 0.19252795 | Z9: =AVERAGE(P9:Y9) -> 0.19285811
B10: PECO | C10: 8431 | D10: 8452 | E10: 8488 | F10: 8492 | G10: 8490 | H10: 8479 | I10: 8485 | J10: 8524 | K10: 8572 | L10: 8602 | O10: PECO | P10: =C10/SUM(C$7:C$12) -> 0.26496747 | Q10: =D10/SUM(D$7:D$12) -> 0.26489485 | R10: =E10/SUM(E$7:E$12) -> 0.26483619 | S10: =F10/SUM(F$7:F$12) -> 0.26435064 | T10: =G10/SUM(G$7:G$12) -> 0.26363185 | U10: =H10/SUM(H$7:H$12) -> 0.26267038 | V10: =I10/SUM(I$7:I$12) -> 0.26176153 | W10: =J10/SUM(J$7:J$12) -> 0.26127203 | ... Y10: =L10/SUM(L$7:L$12) -> 0.26064297 | Z10: =AVERAGE(P10:Y10) -> 0.2630234
B11: PS | C11: 10063 | D11: 10102 | E11: 10176 | F11: 10209 | G11: 10258 | H11: 10297 | I11: 10363 | J11: 10458 | K11: 10522 | L11: 10597 | O11: PS | P11: =C11/SUM(C$7:C$12) -> 0.31625758 | Q11: =D11/SUM(D$7:D$12) -> 0.31660764 | R11: =E11/SUM(E$7:E$12) -> 0.3175039 | S11: =F11/SUM(F$7:F$12) -> 0.31779978 | T11: =G11/SUM(G$7:G$12) -> 0.31853186 | U11: =H11/SUM(H$7:H$12) -> 0.31899009 | V11: =I11/SUM(I$7:I$12) -> 0.31969767 | W11: =J11/SUM(J$7:J$12) -> 0.32055172 | ... Y11: =L11/SUM(L$7:L$12) -> 0.32109202 | Z11: =AVERAGE(P11:Y11) -> 0.31876588
B12: RECO | C12: 404 | D12: 403 | E12: 404 | F12: 404 | G12: 403 | H12: 404 | I12: 405 | J12: 407 | K12: 407 | L12: 410 | O12: RECO | P12: =C12/SUM(C$7:C$12) -> 0.012696816 | Q12: =D12/SUM(D$7:D$12) -> 0.012630457 | R12: =E12/SUM(E$7:E$12) -> 0.012605304 | S12: =F12/SUM(F$7:F$12) -> 0.012576267 | T12: =G12/SUM(G$7:G$12) -> 0.012513973 | U12: =H12/SUM(H$7:H$12) -> 0.012515489 | V12: =I12/SUM(I$7:I$12) -> 0.012494216 | W12: =J12/SUM(J$7:J$12) -> 0.012475096 | ... Y12: =L12/SUM(L$7:L$12) -> 0.012423113 | Z12: =AVERAGE(P12:Y12) -> 0.012533284
A13: PJM_PENE | B13: PENLC | C13: 2822 | D13: 2819 | E13: 2820 | F13: 2823 | G13: 2823 | H13: 2829 | I13: 2832 | J13: 2836 | K13: 2855 | L13: 2873
A14: PJM_SMAC | B14: BGE | C14: 6646 | D14: 6657 | E14: 6682 | F14: 6700 | G14: 6705 | H14: 6723 | I14: 6760 | J14: 6798 | K14: 6828 | L14: 6879 | N14: PJM_SMAC | O14: BGE | P14: =C14/SUM(C$14:C$15) -> 0.52141848 | Q14: =D14/SUM(D$14:D$15) -> 0.5210551 | R14: =E14/SUM(E$14:E$15) -> 0.52121685 | S14: =F14/SUM(F$14:F$15) -> 0.52107637 | T14: =G14/SUM(G$14:G$15) -> 0.52174928 | U14: =H14/SUM(H$14:H$15) -> 0.52258065 | V14: =I14/SUM(I$14:I$15) -> 0.52386857 | W14: =J14/SUM(J$14:J$15) -> 0.52490155 | ... Y14: =L14/SUM(L$14:L$15) -> 0.52785451 | Z14: =AVERAGE(P14:Y14) -> 0.5232167
B15: PEPCO | C15: 6100 | D15: 6119 | E15: 6138 | F15: 6158 | G15: 6146 | H15: 6142 | I15: 6144 | J15: 6153 | K15: 6142 | L15: 6153 | O15: PEPCO | P15: =C15/SUM(C$14:C$15) -> 0.47858152 | Q15: =D15/SUM(D$14:D$15) -> 0.4789449 | R15: =E15/SUM(E$14:E$15) -> 0.47878315 | S15: =F15/SUM(F$14:F$15) -> 0.47892363 | T15: =G15/SUM(G$14:G$15) -> 0.47825072 | U15: =H15/SUM(H$14:H$15) -> 0.47741935 | V15: =I15/SUM(I$14:I$15) -> 0.47613143 | W15: =J15/SUM(J$14:J$15) -> 0.47509845 | ... Y15: =L15/SUM(L$14:L$15) -> 0.47214549 | Z15: =AVERAGE(P15:Y15) -> 0.4767833
A16: PJM_WMAC | B16: METED | C16: 2975 | D16: 2975 | E16: 2984 | F16: 2996 | G16: 3012 | H16: 3026 | I16: 3045 | J16: 3059 | K16: 3080 | L16: 3103 | N16: PJM_WMAC | O16: METED | P16: =C16/SUM(C$16:C$17) -> 0.28939689 | Q16: =D16/SUM(D$16:D$17) -> 0.28956589 | R16: =E16/SUM(E$16:E$17) -> 0.28968061 | S16: =F16/SUM(F$16:F$17) -> 0.28935677 | T16: =G16/SUM(G$16:G$17) -> 0.28992203 | U16: =H16/SUM(H$16:H$17) -> 0.29015246 | V16: =I16/SUM(I$16:I$17) -> 0.29116466 | W16: =J16/SUM(J$16:J$17) -> 0.29130559 | ... Y16: =L16/SUM(L$16:L$17) -> 0.29122478 | Z16: =AVERAGE(P16:Y16) -> 0.29032707
B17: PL | C17: 7305 | D17: 7299 | E17: 7317 | F17: 7358 | G17: 7377 | H17: 7403 | I17: 7413 | J17: 7442 | K17: 7486 | L17: 7552 | O17: PL + UGI | P17: =C17/SUM(C$16:C$17) -> 0.71060311 | Q17: =D17/SUM(D$16:D$17) -> 0.71043411 | R17: =E17/SUM(E$16:E$17) -> 0.71031939 | S17: =F17/SUM(F$16:F$17) -> 0.71064323 | T17: =G17/SUM(G$16:G$17) -> 0.71007797 | U17: =H17/SUM(H$16:H$17) -> 0.70984754 | V17: =I17/SUM(I$16:I$17) -> 0.70883534 | W17: =J17/SUM(J$16:J$17) -> 0.70869441 | ... Y17: =L17/SUM(L$16:L$17) -> 0.70877522 | Z17: =AVERAGE(P17:Y17) -> 0.70967293
A18: PJM_West | B18: AEP | C18: 22286 | D18: 22385 | E18: 22521 | F18: 22573 | G18: 22595 | H18: 22631 | I18: 22706 | J18: 22782 | K18: 22877 | L18: 22935 | N18: PJM_West | O18: AEP | P18: =C18/SUM(C$18:C$23) -> 0.62280971 | Q18: =D18/SUM(D$18:D$23) -> 0.62225496 | R18: =E18/SUM(E$18:E$23) -> 0.62186939 | S18: =F18/SUM(F$18:F$23) -> 0.62093912 | T18: =G18/SUM(G$18:G$23) -> 0.62007739 | U18: =H18/SUM(H$18:H$23) -> 0.6197727 | V18: =I18/SUM(I$18:I$23) -> 0.62038251 | W18: =J18/SUM(J$18:J$23) -> 0.62057694 | ... Y18: =L18/SUM(L$18:L$23) -> 0.62048535 | Z18: =AVERAGE(P18:Y18) -> 0.62097633
B19: DAY | C19: 3293 | D19: 3296 | E19: 3309 | F19: 3316 | G19: 3321 | H19: 3321 | I19: 3314 | J19: 3320 | K19: 3339 | L19: 3344 | O19: DAY | P19: =C19/SUM(C$18:C$23) -> 0.09202694 | Q19: =D19/SUM(D$18:D$23) -> 0.091621727 | R19: =E19/SUM(E$18:E$23) -> 0.091370979 | S19: =F19/SUM(F$18:F$23) -> 0.091216681 | T19: =G19/SUM(G$18:G$23) -> 0.091138615 | U19: =H19/SUM(H$18:H$23) -> 0.090948925 | V19: =I19/SUM(I$18:I$23) -> 0.090546448 | W19: =J19/SUM(J$18:J$23) -> 0.090436109 | ... Y19: =L19/SUM(L$18:L$23) -> 0.090468847 | Z19: =AVERAGE(P19:Y19) -> 0.09103539
B20: DEOK | C20: 5261 | D20: 5306 | E20: 5347 | F20: 5376 | G20: 5403 | H20: 5421 | I20: 5426 | J20: 5441 | K20: 5468 | L20: 5481 | O20: DEOK | P20: =C20/SUM(C$18:C$23) -> 0.14702512 | Q20: =D20/SUM(D$18:D$23) -> 0.14749541 | R20: =E20/SUM(E$18:E$23) -> 0.147646 | S20: =F20/SUM(F$18:F$23) -> 0.14788326 | T20: =G20/SUM(G$18:G$23) -> 0.1482752 | U20: =H20/SUM(H$18:H$23) -> 0.14845954 | V20: =I20/SUM(I$18:I$23) -> 0.14825137 | W20: =J20/SUM(J$18:J$23) -> 0.14821171 | ... Y20: =L20/SUM(L$18:L$23) -> 0.14828342 | Z20: =AVERAGE(P20:Y20) -> 0.1479864
B21: DLCO | C21: 2756 | D21: 2773 | E21: 2797 | F21: 2821 | G21: 2828 | H21: 2836 | I21: 2842 | J21: 2850 | K21: 2857 | L21: 2872 | O21: DLCO | P21: =C21/SUM(C$18:C$23) -> 0.077019814 | Q21: =D21/SUM(D$18:D$23) -> 0.077083449 | R21: =E21/SUM(E$18:E$23) -> 0.077233191 | S21: =F21/SUM(F$18:F$23) -> 0.077600198 | T21: =G21/SUM(G$18:G$23) -> 0.077609155 | U21: =H21/SUM(H$18:H$23) -> 0.077666712 | V21: =I21/SUM(I$18:I$23) -> 0.077650273 | W21: =J21/SUM(J$18:J$23) -> 0.077633407 | ... Y21: =L21/SUM(L$18:L$23) -> 0.077699321 | Z21: =AVERAGE(P21:Y21) -> 0.077469871
B22: EKPC | C22: 2097 | D22: 2124 | E22: 2151 | F22: 2177 | G22: 2202 | H22: 2216 | I22: 2222 | J22: 2228 | K22: 2232 | L22: 2241 | O22: EKPC | P22: =C22/SUM(C$18:C$23) -> 0.058603247 | Q22: =D22/SUM(D$18:D$23) -> 0.059042642 | R22: =E22/SUM(E$18:E$23) -> 0.059395278 | S22: =F22/SUM(F$18:F$23) -> 0.059885016 | T22: =G22/SUM(G$18:G$23) -> 0.060429759 | U22: =H22/SUM(H$18:H$23) -> 0.060687389 | V22: =I22/SUM(I$18:I$23) -> 0.060710383 | W22: =J22/SUM(J$18:J$23) -> 0.060690256 | ... Y22: =L22/SUM(L$18:L$23) -> 0.060628196 | Z22: =AVERAGE(P22:Y22) -> 0.060062068
B23: OVEC | C23: 90 | D23: 90 | E23: 90 | F23: 90 | G23: 90 | H23: 90 | I23: 90 | J23: 90 | K23: 90 | L23: 90 | O23: OVEC | P23: =C23/SUM(C$18:C$23) -> 0.0025151608 | Q23: =D23/SUM(D$18:D$23) -> 0.0025018069 | R23: =E23/SUM(E$18:E$23) -> 0.0024851581 | S23: =F23/SUM(F$18:F$23) -> 0.0024757241 | T23: =G23/SUM(G$18:G$23) -> 0.0024698812 | U23: =H23/SUM(H$18:H$23) -> 0.0024647405 | V23: =I23/SUM(I$18:I$23) -> 0.0024590164 | W23: =J23/SUM(J$18:J$23) -> 0.0024515813 | ... Y23: =L23/SUM(L$18:L$23) -> 0.0024348673 | Z23: =AVERAGE(P23:Y23) -> 0.0024699409
B24: UGI | C24: 193 | D24: 193 | E24: 193 | F24: 193 | G24: 193 | H24: 192 | I24: 192 | J24: 192 | K24: 192 | L24: 193
B25: RTO | C25: 151942.07 | D25: 152966.66 | E25: 154291.93 | F25: 155433.91 | G25: 156483.94 | H25: 157061.13 | I25: 157770.51 | J25: 158690.06 | K25: 159622.16 | L25: 160512.9
B26: MISO4 | C26: 9989 | D26: 10075 | E26: 10144 | F26: 10196 | G26: 10246 | H26: 10303 | I26: 10353 | J26: 10396 | K26: 10439 | L26: 10492
B29: PL + UGI | C29: 7305 | D29: 7299 | E29: 7317 | F29: 7358 | G29: 7377 | H29: 7403 | I29: 7413 | J29: 7442 | K29: 7486 | L29: 7552

Sheet Load Zones to States
A1: Convert to state
A2: Load zone | B2: state | C2: factor | D2: Transmission/Load Zones (21 unique black boldfaces) | E2: IPM Regions | F2: State Name | H2: IPM Regions | I2: LDA-style zone name | J2: Load zone
A3: AE | B3: NJ | C3: 1 | D3: AE [AECO] | E3: =_xlfn.XLOOKUP(D3,I:I,H:H,,0,1) -> PJM_EMAC | F3: New Jersey | H3: PJM_COMD | I3: ComEd | J3: COMED
A4: AEP | B4: IN | C4: 0.18 | D4: AEP | E4: =_xlfn.XLOOKUP(D4,I:I,H:H,,0,1) -> PJM_West | F4: Indiana | H4: PJM_West | I4: AEP | J4: AEP
A5: AEP | B5: KY | C5: 0.05 | D5: AEP | E5: =_xlfn.XLOOKUP(D5,I:I,H:H,,0,1) -> PJM_West | F5: Kentucky | H5: PJM_West | I5: Dayton [DAY] | J5: DAY
A6: AEP | B6: MI | C6: 0.04 | D6: AEP | E6: =_xlfn.XLOOKUP(D6,I:I,H:H,,0,1) -> PJM_West | F6: Michigan | H6: PJM_West | I6: Duquesne [DLCO or DUQ] | J6: DLCO
A7: AEP | B7: OH | C7: 0.43 | D7: AEP | E7: =_xlfn.XLOOKUP(D7,I:I,H:H,,0,1) -> PJM_West | F7: Ohio | H7: PJM_AP | I7: APS [AP] | J7: APS
A8: AEP | B8: TN | C8: 0.02 | D8: AEP | E8: =_xlfn.XLOOKUP(D8,I:I,H:H,,0,1) -> PJM_West | F8: Tennessee | H8: PJM_ATSI | I8: ATSI | J8: ATSI
A9: AEP | B9: VA | C9: 0.15 | D9: AEP | E9: =_xlfn.XLOOKUP(D9,I:I,H:H,,0,1) -> PJM_West | F9: Virginia | H9: PJM_West | I9: DEOK | J9: DEOK
A10: AEP | B10: WV | C10: 0.14 | D10: AEP | E10: =_xlfn.XLOOKUP(D10,I:I,H:H,,0,1) -> PJM_West | F10: West Virginia | H10: PJM_West | I10: EKPC | J10: EKPC
A11: APS | B11: MD | C11: 0.17 | D11: APS [AP] | E11: =_xlfn.XLOOKUP(D11,I:I,H:H,,0,1) -> PJM_AP | F11: Maryland | H11: PJM_West | I11: OVEC | J11: OVEC
A12: APS | B12: PA | C12: 0.44 | D12: APS [AP] | E12: =_xlfn.XLOOKUP(D12,I:I,H:H,,0,1) -> PJM_AP | F12: Pennsylvania | H12: PJM_Dom | I12: Dominion [DOM] | J12: DOM
A13: APS | B13: VA | C13: 0.07 | D13: APS [AP] | E13: =_xlfn.XLOOKUP(D13,I:I,H:H,,0,1) -> PJM_AP | F13: Virginia | H13: PJM_WMAC | I13: MetEd | J13: METED
A14: APS | B14: WV | C14: 0.32 | D14: APS [AP] | E14: =_xlfn.XLOOKUP(D14,I:I,H:H,,0,1) -> PJM_AP | F14: West Virginia | H14: PJM_WMAC | I14: PPL [PL]+UGI | J14: PL
... A23: DOM | B23: NC | C23: 0.05 | D23: Dominion [DOM] | E23: =_xlfn.XLOOKUP(D23,I:I,H:H,,0,1) -> PJM_Dom | F23: North Carolina | H23: PJM_SMAC | I23: PEPCO | J23: PEPCO
A24: DOM | B24: VA | C24: 0.95 | D24: Dominion [DOM] | E24: =_xlfn.XLOOKUP(D24,I:I,H:H,,0,1) -> PJM_Dom | F24: Virginia
A25: DPL | B25: DE | C25: 0.61 | D25: DPL | E25: =_xlfn.XLOOKUP(D25,I:I,H:H,,0,1) -> PJM_EMAC | F25: Delaware
A26: DPL | B26: MD | C26: 0.36 | D26: DPL | E26: =_xlfn.XLOOKUP(D26,I:I,H:H,,0,1) -> PJM_EMAC | F26: Maryland
A27: DPL | B27: VA | C27: 0.03 | D27: DPL | E27: =_xlfn.XLOOKUP(D27,I:I,H:H,,0,1) -> PJM_EMAC | F27: Virginia
A28: EKPC | B28: KY | C28: 1 | D28: EKPC | E28: =_xlfn.XLOOKUP(D28,I:I,H:H,,0,1) -> PJM_West | F28: Kentucky
A29: JCPL | B29: NJ | C29: 1 | D29: JCPL | E29: =_xlfn.XLOOKUP(D29,I:I,H:H,,0,1) -> PJM_EMAC | F29: New Jersey
A30: METED | B30: PA | C30: 1 | D30: MetEd | E30: =_xlfn.XLOOKUP(D30,I:I,H:H,,0,1) -> PJM_WMAC | F30: Pennsylvania
A31: OVEC | B31: OH | C31: 1 | D31: OVEC | E31: =_xlfn.XLOOKUP(D31,I:I,H:H,,0,1) -> PJM_West | F31: Ohio
A32: PECO | B32: PA | C32: 1 | D32: PECO | E32: =_xlfn.XLOOKUP(D32,I:I,H:H,,0,1) -> PJM_EMAC | F32: Pennsylvania
A33: PENLC | B33: PA | C33: 1 | D33: Penelec [PENLC] | E33: =_xlfn.XLOOKUP(D33,I:I,H:H,,0,1) -> PJM_PENE | F33: Pennsylvania
A34: PEPCO | B34: DC | C34: 0.3 | D34: PEPCO | E34: =_xlfn.XLOOKUP(D34,I:I,H:H,,0,1) -> PJM_SMAC | F34: District of Columbia
A35: PEPCO | B35: MD | C35: 0.7 | D35: PEPCO | E35: =_xlfn.XLOOKUP(D35,I:I,H:H,,0,1) -> PJM_SMAC | F35: Maryland
... A39: UGI | B39: PA | C39: 1 | D39: PPL [PL]+UGI | E39: =_xlfn.XLOOKUP(D39,I:I,H:H,,0,1) -> PJM_WMAC | F39: Pennsylvania
A40: MISO4 | B40: IL | C40: 1 | F40: Illinois
A41: SUM | F41: 0
